Workbook

Sheet Premissas
A1: PLANO DE NEGÓCIOS — REVENDA DE GÁS E ÁGUA MINERAL
A2: Supermercado Multishow — Anchieta/ES
A3: Data: Agosto/2026
A5: DADOS DO NEGÓCIO
A6: Modelo | B6: Revenda independente (bandeira branca)
A7: Localização | B7: Rua de trás do Supermercado Multishow, Anchieta/ES
A8: Classe de armazenamento | B8: Classe II (até 120 botijões P13)
A9: Imóvel | B9: Próprio — custo zero de aluguel
A10: População Anchieta (2025) | B10: ~33.000 habitantes / ~10.000 domicílios
A12: PREMISSAS DE PREÇO E CUSTO
A13: Item | B13: Valor | C13: Unidade | D13: Fonte / Nota
A14: Preço venda — Gás P13 | B14: 106 | C14: R$/botijão | D14: Média ES — Googás/ANP
A15: Custo compra — Gás P13 | B15: 80 | C15: R$/botijão | D15: Estimativa negociação bandeira branca
A16: Margem bruta — Gás P13 | B16: =B14-B15 | C16: R$/botijão | D16: Fórmula: Preço - Custo
A18: Preço venda — Água 20L | B18: 11.5 | C18: R$/galão | D18: Média mercado local
A19: Custo compra — Água 20L | B19: 4.5 | C19: R$/galão | D19: Preço atacado ES
A20: Margem bruta — Água 20L | B20: =B18-B19 | C20: R$/galão | D20: Fórmula: Preço - Custo
A22: Dias de operação/mês | B22: 26 | C22: dias | D22: Seg-Sáb
A23: Alíquota Simples Nacional | B23: 0.06 | C23: % | D23: Faixa estimada — comércio
A24: Custo entrega (combustível) | B24: 800 | C24: R$/mês | D24: Moto/utilitário — estimativa
A26: PREMISSAS DE VOLUME (vendas/dia)
A27: Item | B27: Pessimista | C27: Realista | D27: Otimista
A28: Gás P13 (botijões/dia) | B28: 8 | C28: 15 | D28: 25
A29: Água 20L (galões/dia) | B29: 10 | C29: 20 | D29: 30
A31: VOLUME MENSAL (calculado)
A32: Item | B32: Pessimista | C32: Realista | D32: Otimista
A33: Gás P13 (botijões/mês) | B33: =B28*B22 | C33: =C28*B22 | D33: =D28*B22
A34: Água 20L (galões/mês) | B34: =B29*B22 | C34: =C29*B22 | D34: =D29*B22
A36: INVESTIMENTO INICIAL
A37: Item | B37: Valor (R$) | D37: Nota
A38: Concretagem do piso (~50m²) | B38: 3500 | D38: Estimativa — piso de concreto
A39: Cobertura (telha metálica) | B39: 5000 | D39: Estrutura metálica simples + telha
A40: Sinalização + demarcação | B40: 500 | D40: Placas obrigatórias + pintura de piso
A41: Extintores (2x PQS) | B41: 500 | D41: Compra + suporte
A42: Balança comercial | B42: 400 | D42: Obrigatória por lei
A43: Instalação elétrica (adequação) | B43: 1000 | D43: Redirecionar pontos fora da zona 3m
A44: Licenças e taxas (ANP, Bombeiros, Prefeitura) | B44: 3000 | D44: Estimativa — pode variar
A45: Abertura/alteração CNPJ + CNAE | B45: 2000 | D45: Contador + taxas
A46: Estoque inicial — Gás (80 botijões) | B46: =80*B15 | D46: Fórmula
A47: Estoque inicial — Água (150 galões) | B47: =150*B19 | D47: Fórmula
...

Sheet DRE 12 Meses
A1: DRE PROJETADA — 12 MESES — CENÁRIO REALISTA
A2: Revenda Gás e Água — Multishow Anchieta/ES
A4: Item | B4: Mês 1 | C4: Mês 2 | D4: Mês 3 | E4: Mês 4 | F4: Mês 5 | G4: Mês 6 | H4: Mês 7 | I4: Mês 8 | J4: Mês 9 | K4: Mês 10 | L4: Mês 11 | M4: Mês 12 | N4: Total 12M
A5: Fator de ramp-up | B5: 0.5 | C5: 0.65 | D5: 0.8 | E5: 0.9 | F5: 0.95 | G5: 1 | H5: 1 | I5: 1 | J5: 1 | K5: 1 | L5: 1 | M5: 1
A7: VOLUME DE VENDAS
A8: Gás P13 (botijões) | B8: ='Premissas'!C33*B5 | C8: ='Premissas'!C33*C5 | D8: ='Premissas'!C33*D5 | E8: ='Premissas'!C33*E5 | F8: ='Premissas'!C33*F5 | G8: ='Premissas'!C33*G5 | H8: ='Premissas'!C33*H5 | I8: ='Premissas'!C33*I5 | J8: ='Premissas'!C33*J5 | K8: ='Premissas'!C33*K5 | L8: ='Premissas'!C33*L5 | M8: ='Premissas'!C33*M5 | N8: =SUM(B8:M8)
A9: Água 20L (galões) | B9: ='Premissas'!C34*B5 | C9: ='Premissas'!C34*C5 | D9: ='Premissas'!C34*D5 | E9: ='Premissas'!C34*E5 | F9: ='Premissas'!C34*F5 | G9: ='Premissas'!C34*G5 | H9: ='Premissas'!C34*H5 | I9: ='Premissas'!C34*I5 | J9: ='Premissas'!C34*J5 | K9: ='Premissas'!C34*K5 | L9: ='Premissas'!C34*L5 | M9: ='Premissas'!C34*M5 | N9: =SUM(B9:M9)
A11: RECEITA BRUTA
A12: Receita — Gás P13 | B12: =B8*'Premissas'!B14 | C12: =C8*'Premissas'!B14 | D12: =D8*'Premissas'!B14 | E12: =E8*'Premissas'!B14 | F12: =F8*'Premissas'!B14 | G12: =G8*'Premissas'!B14 | H12: =H8*'Premissas'!B14 | I12: =I8*'Premissas'!B14 | J12: =J8*'Premissas'!B14 | K12: =K8*'Premissas'!B14 | L12: =L8*'Premissas'!B14 | M12: =M8*'Premissas'!B14 | N12: =SUM(B12:M12)
A13: Receita — Água 20L | B13: =B9*'Premissas'!B18 | C13: =C9*'Premissas'!B18 | D13: =D9*'Premissas'!B18 | E13: =E9*'Premissas'!B18 | F13: =F9*'Premissas'!B18 | G13: =G9*'Premissas'!B18 | H13: =H9*'Premissas'!B18 | I13: =I9*'Premissas'!B18 | J13: =J9*'Premissas'!B18 | K13: =K9*'Premissas'!B18 | L13: =L9*'Premissas'!B18 | M13: =M9*'Premissas'!B18 | N13: =SUM(B13:M13)
A14: RECEITA BRUTA TOTAL | B14: =B12+B13 | C14: =C12+C13 | D14: =D12+D13 | E14: =E12+E13 | F14: =F12+F13 | G14: =G12+G13 | H14: =H12+H13 | I14: =I12+I13 | ... M14: =M12+M13 | N14: =SUM(B14:M14)
A16: IMPOSTOS (Simples Nacional) | B16: =B14*'Premissas'!B23 | C16: =C14*'Premissas'!B23 | D16: =D14*'Premissas'!B23 | E16: =E14*'Premissas'!B23 | F16: =F14*'Premissas'!B23 | G16: =G14*'Premissas'!B23 | H16: =H14*'Premissas'!B23 | I16: =I14*'Premissas'!B23 | J16: =J14*'Premissas'!B23 | K16: =K14*'Premissas'!B23 | L16: =L14*'Premissas'!B23 | M16: =M14*'Premissas'!B23 | N16: =SUM(B16:M16)
A17: RECEITA LÍQUIDA | B17: =B14-B16 | C17: =C14-C16 | D17: =D14-D16 | E17: =E14-E16 | F17: =F14-F16 | G17: =G14-G16 | H17: =H14-H16 | I17: =I14-I16 | ... M17: =M14-M16 | N17: =SUM(B17:M17)
A19: CUSTO DAS MERCADORIAS (CMV)
A20: CMV — Gás P13 | B20: =B8*'Premissas'!B15 | C20: =C8*'Premissas'!B15 | D20: =D8*'Premissas'!B15 | E20: =E8*'Premissas'!B15 | F20: =F8*'Premissas'!B15 | G20: =G8*'Premissas'!B15 | H20: =H8*'Premissas'!B15 | I20: =I8*'Premissas'!B15 | J20: =J8*'Premissas'!B15 | K20: =K8*'Premissas'!B15 | L20: =L8*'Premissas'!B15 | M20: =M8*'Premissas'!B15 | N20: =SUM(B20:M20)
A21: CMV — Água 20L | B21: =B9*'Premissas'!B19 | C21: =C9*'Premissas'!B19 | D21: =D9*'Premissas'!B19 | E21: =E9*'Premissas'!B19 | F21: =F9*'Premissas'!B19 | G21: =G9*'Premissas'!B19 | H21: =H9*'Premissas'!B19 | I21: =I9*'Premissas'!B19 | J21: =J9*'Premissas'!B19 | K21: =K9*'Premissas'!B19 | L21: =L9*'Premissas'!B19 | M21: =M9*'Premissas'!B19 | N21: =SUM(B21:M21)
A22: CMV TOTAL | B22: =B20+B21 | C22: =C20+C21 | D22: =D20+D21 | E22: =E20+E21 | F22: =F20+F21 | G22: =G20+G21 | H22: =H20+H21 | I22: =I20+I21 | ... M22: =M20+M21 | N22: =SUM(B22:M22)
A24: LUCRO BRUTO | B24: =B17-B22 | C24: =C17-C22 | D24: =D17-D22 | E24: =E17-E22 | F24: =F17-F22 | G24: =G17-G22 | H24: =H17-H22 | I24: =I17-I22 | ... M24: =M17-M22 | N24: =SUM(B24:M24)
A25: Margem Bruta % | B25: =IF(B14=0,0,B24/B14) | C25: =IF(C14=0,0,C24/C14) | D25: =IF(D14=0,0,D24/D14) | E25: =IF(E14=0,0,E24/E14) | F25: =IF(F14=0,0,F24/F14) | G25: =IF(G14=0,0,G24/G14) | H25: =IF(H14=0,0,H24/H14) | I25: =IF(I14=0,0,I24/I14) | ... N25: =IF(N14=0,0,N24/N14)
A27: CUSTOS FIXOS
A28: Funcionário + encargos | B28: ='Premissas'!B56 | C28: ='Premissas'!B56 | D28: ='Premissas'!B56 | E28: ='Premissas'!B56 | F28: ='Premissas'!B56 | G28: ='Premissas'!B56 | H28: ='Premissas'!B56 | I28: ='Premissas'!B56 | J28: ='Premissas'!B56 | K28: ='Premissas'!B56 | L28: ='Premissas'!B56 | M28: ='Premissas'!B56 | N28: =SUM(B28:M28)
A29: Contador | B29: ='Premissas'!B57 | C29: ='Premissas'!B57 | D29: ='Premissas'!B57 | E29: ='Premissas'!B57 | F29: ='Premissas'!B57 | G29: ='Premissas'!B57 | H29: ='Premissas'!B57 | I29: ='Premissas'!B57 | J29: ='Premissas'!B57 | K29: ='Premissas'!B57 | L29: ='Premissas'!B57 | M29: ='Premissas'!B57 | N29: =SUM(B29:M29)
A30: Energia + água + internet | B30: ='Premissas'!B58+'Premissas'!B59 | C30: ='Premissas'!B58+'Premissas'!B59 | D30: ='Premissas'!B58+'Premissas'!B59 | E30: ='Premissas'!B58+'Premissas'!B59 | F30: ='Premissas'!B58+'Premissas'!B59 | G30: ='Premissas'!B58+'Premissas'!B59 | H30: ='Premissas'!B58+'Premissas'!B59 | I30: ='Premissas'!B58+'Premissas'!B59 | J30: ='Premissas'!B58+'Premissas'!B59 | K30: ='Premissas'!B58+'Premissas'!B59 | L30: ='Premissas'!B58+'Premissas'!B59 | M30: ='Premissas'!B58+'Premissas'!B59 | N30: =SUM(B30:M30)
A31: Manutenção | B31: ='Premissas'!B60 | C31: ='Premissas'!B60 | D31: ='Premissas'!B60 | E31: ='Premissas'!B60 | F31: ='Premissas'!B60 | G31: ='Premissas'!B60 | H31: ='Premissas'!B60 | I31: ='Premissas'!B60 | J31: ='Premissas'!B60 | K31: ='Premissas'!B60 | L31: ='Premissas'!B60 | M31: ='Premissas'!B60 | N31: =SUM(B31:M31)
A32: Entrega (combustível) | B32: ='Premissas'!B62 | C32: ='Premissas'!B62 | D32: ='Premissas'!B62 | E32: ='Premissas'!B62 | F32: ='Premissas'!B62 | G32: ='Premissas'!B62 | H32: ='Premissas'!B62 | I32: ='Premissas'!B62 | J32: ='Premissas'!B62 | K32: ='Premissas'!B62 | L32: ='Premissas'!B62 | M32: ='Premissas'!B62 | N32: =SUM(B32:M32)
A33: Marketing | B33: ='Premissas'!B63 | C33: ='Premissas'!B63 | D33: ='Premissas'!B63 | E33: ='Premissas'!B63 | F33: ='Premissas'!B63 | G33: ='Premissas'!B63 | H33: ='Premissas'!B63 | I33: ='Premissas'!B63 | J33: ='Premissas'!B63 | K33: ='Premissas'!B63 | L33: ='Premissas'!B63 | M33: ='Premissas'!B63 | N33: =SUM(B33:M33)
A34: TOTAL CUSTOS FIXOS | B34: =SUM(B28:B33) | C34: =SUM(C28:C33) | D34: =SUM(D28:D33) | E34: =SUM(E28:E33) | F34: =SUM(F28:F33) | G34: =SUM(G28:G33) | H34: =SUM(H28:H33) | I34: =SUM(I28:I33) | ... M34: =SUM(M28:M33) | N34: =SUM(B34:M34)
A36: LUCRO OPERACIONAL (EBITDA) | B36: =B24-B34 | C36: =C24-C34 | D36: =D24-D34 | E36: =E24-E34 | F36: =F24-F34 | G36: =G24-G34 | H36: =H24-H34 | I36: =I24-I34 | ... M36: =M24-M34 | N36: =SUM(B36:M36)
A37: Margem EBITDA % | B37: =IF(B14=0,0,B36/B14) | C37: =IF(C14=0,0,C36/C14) | D37: =IF(D14=0,0,D36/D14) | E37: =IF(E14=0,0,E36/E14) | F37: =IF(F14=0,0,F36/F14) | G37: =IF(G14=0,0,G36/G14) | H37: =IF(H14=0,0,H36/H14) | I37: =IF(I14=0,0,I36/I14) | ... N37: =IF(N14=0,0,N36/N14)
A39: LUCRO ACUMULADO | B39: =B36 | C39: =B39+C36 | D39: =C39+D36 | E39: =D39+E36 | F39: =E39+F36 | G39: =F39+G36 | H39: =G39+H36 | I39: =H39+I36 | J39: =I39+J36 | ... M39: =L39+M36 | N39: =M39

Sheet Cenários
A1: COMPARATIVO DE CENÁRIOS — RESUMO ANUAL
A3: Indicador | B3: Pessimista | C3: Realista | D3: Otimista
A4: Gás P13 — vendas/mês (maduro) | B4: ='Premissas'!B33 | C4: ='Premissas'!C33 | D4: ='Premissas'!D33
A5: Água 20L — vendas/mês (maduro) | B5: ='Premissas'!B34 | C5: ='Premissas'!C34 | D5: ='Premissas'!D34
A7: Receita mensal — Gás (madura) | B7: ='Premissas'!B33*'Premissas'!B14 | C7: ='Premissas'!C33*'Premissas'!B14 | D7: ='Premissas'!D33*'Premissas'!B14
A8: Receita mensal — Água (madura) | B8: ='Premissas'!B34*'Premissas'!B18 | C8: ='Premissas'!C34*'Premissas'!B18 | D8: ='Premissas'!D34*'Premissas'!B18
A9: RECEITA MENSAL TOTAL | B9: =B7+B8 | C9: =C7+C8 | D9: =D7+D8
A11: CMV mensal — Gás | B11: ='Premissas'!B33*'Premissas'!B15 | C11: ='Premissas'!C33*'Premissas'!B15 | D11: ='Premissas'!D33*'Premissas'!B15
A12: CMV mensal — Água | B12: ='Premissas'!B34*'Premissas'!B19 | C12: ='Premissas'!C34*'Premissas'!B19 | D12: ='Premissas'!D34*'Premissas'!B19
A13: CMV MENSAL TOTAL | B13: =B11+B12 | C13: =C11+C12 | D13: =D11+D12
A15: Impostos (Simples) | B15: =B9*'Premissas'!B23 | C15: =C9*'Premissas'!B23 | D15: =D9*'Premissas'!B23
A16: Custos fixos mensais | B16: ='Premissas'!B65 | C16: ='Premissas'!B65 | D16: ='Premissas'!B65
A18: LUCRO OPERACIONAL/MÊS | B18: =B9-B13-B15-B16 | C18: =C9-C13-C15-C16 | D18: =D9-D13-D15-D16
A19: Margem operacional % | B19: =IF(B9=0,0,B18/B9) | C19: =IF(C9=0,0,C18/C9) | D19: =IF(D9=0,0,D18/D9)
A21: LUCRO ANUAL (12 meses) | B21: =B18*12 | C21: =C18*12 | D21: =D18*12
A22: Investimento inicial | B22: ='Premissas'!B51 | C22: ='Premissas'!B51 | D22: ='Premissas'!B51
A23: Payback (meses) | B23: =IF(B18<=0,"N/A",B22/B18) | C23: =IF(C18<=0,"N/A",C22/C18) | D23: =IF(D18<=0,"N/A",D22/D18)
A24: ROI anual | B24: =IF(B22=0,0,B21/B22) | C24: =IF(C22=0,0,C21/C22) | D24: =IF(D22=0,0,D21/D22)

Sheet Fluxo de Caixa
A1: FLUXO DE CAIXA — 12 MESES — CENÁRIO REALISTA
A3: Item | B3: Mês 0 (Investimento) | C3: Mês 1 | D3: Mês 2 | E3: Mês 3 | F3: Mês 4 | G3: Mês 5 | H3: Mês 6 | I3: Mês 7 | J3: Mês 8 | K3: Mês 9 | L3: Mês 10 | M3: Mês 11 | N3: Mês 12
A4: ENTRADAS
A5: Receita bruta | C5: ='DRE 12 Meses'!B14 | D5: ='DRE 12 Meses'!C14 | E5: ='DRE 12 Meses'!D14 | F5: ='DRE 12 Meses'!E14 | G5: ='DRE 12 Meses'!F14 | H5: ='DRE 12 Meses'!G14 | I5: ='DRE 12 Meses'!H14 | J5: ='DRE 12 Meses'!I14 | ... N5: ='DRE 12 Meses'!M14
A7: SAÍDAS
A8: Investimento inicial | B8: ='Premissas'!B51 | C8: 0 | D8: 0 | E8: 0 | F8: 0 | G8: 0 | H8: 0 | I8: 0 | J8: 0 | K8: 0 | L8: 0 | M8: 0 | N8: 0
A9: CMV (compra de mercadoria) | C9: ='DRE 12 Meses'!B22 | D9: ='DRE 12 Meses'!C22 | E9: ='DRE 12 Meses'!D22 | F9: ='DRE 12 Meses'!E22 | G9: ='DRE 12 Meses'!F22 | H9: ='DRE 12 Meses'!G22 | I9: ='DRE 12 Meses'!H22 | J9: ='DRE 12 Meses'!I22 | ... N9: ='DRE 12 Meses'!M22
A10: Impostos | C10: ='DRE 12 Meses'!B16 | D10: ='DRE 12 Meses'!C16 | E10: ='DRE 12 Meses'!D16 | F10: ='DRE 12 Meses'!E16 | G10: ='DRE 12 Meses'!F16 | H10: ='DRE 12 Meses'!G16 | I10: ='DRE 12 Meses'!H16 | J10: ='DRE 12 Meses'!I16 | ... N10: ='DRE 12 Meses'!M16
A11: Custos fixos | C11: ='DRE 12 Meses'!B34 | D11: ='DRE 12 Meses'!C34 | E11: ='DRE 12 Meses'!D34 | F11: ='DRE 12 Meses'!E34 | G11: ='DRE 12 Meses'!F34 | H11: ='DRE 12 Meses'!G34 | I11: ='DRE 12 Meses'!H34 | J11: ='DRE 12 Meses'!I34 | ... N11: ='DRE 12 Meses'!M34
A12: Total saídas | B12: =SUM(B8:B11) | C12: =SUM(C8:C11) | D12: =SUM(D8:D11) | E12: =SUM(E8:E11) | F12: =SUM(F8:F11) | G12: =SUM(G8:G11) | H12: =SUM(H8:H11) | I12: =SUM(I8:I11) | ... N12: =SUM(N8:N11)
A14: SALDO DO MÊS | B14: =B4-B12 | C14: =C5-C12 | D14: =D5-D12 | E14: =E5-E12 | F14: =F5-F12 | G14: =G5-G12 | H14: =H5-H12 | I14: =I5-I12 | J14: =J5-J12 | ... N14: =N5-N12
A15: SALDO ACUMULADO | B15: =B14 | C15: =B15+C14 | D15: =C15+D14 | E15: =D15+E14 | F15: =E15+F14 | G15: =F15+G14 | H15: =G15+H14 | I15: =H15+I14 | J15: =I15+J14 | ... N15: =M15+N14

Sheet Breakeven
A1: ANÁLISE DE BREAKEVEN (Ponto de Equilíbrio)
A3: BREAKEVEN MENSAL — Quantas unidades preciso vender para cobrir custos fixos?
A5: Indicador | B5: Gás P13 | C5: Água 20L | D5: Nota
A6: Preço de venda unitário | B6: ='Premissas'!B14 | C6: ='Premissas'!B18
A7: Custo unitário (CMV) | B7: ='Premissas'!B15 | C7: ='Premissas'!B19
A8: Imposto unitário (Simples) | B8: =B6*'Premissas'!B23 | C8: =C6*'Premissas'!B23
A9: Margem de contribuição unitária | B9: =B6-B7-B8 | C9: =C6-C7-C8 | D9: Quanto sobra por unidade vendida após CMV e imposto
A11: Custos fixos totais/mês | B11: ='Premissas'!B65
A13: Breakeven — só gás (unidades/mês) | B13: =IF(B9=0,0,B11/B9) | D13: Se vendesse APENAS gás
A14: Breakeven — só gás (unidades/dia) | B14: =IF(B9=0,0,B13/26)
A16: Breakeven — só água (unidades/mês) | C16: =IF(C9=0,0,B11/C9) | D16: Se vendesse APENAS água
A17: Breakeven — só água (unidades/dia) | C17: =IF(C9=0,0,C16/26)
A19: Breakeven — MIX (premissa: 60% receita gás, 40% água)
A20: Margem contribuição ponderada | B20: =B9*0.6+C9*0.4 | D20: Média ponderada considerando mix de produtos
A21: Breakeven mix (unidades totais/mês) | B21: =IF(B20=0,0,B11/B20) | D21: Combinando gás + água
A22: Breakeven mix (unidades totais/dia) | B22: =IF(B20=0,0,B21/26)

Sheet Sensibilidade
A1: ANÁLISE DE SENSIBILIDADE — O QUE ACONTECE SE...
A3: Impacto no lucro operacional mensal (cenário realista maduro) quando uma variável muda
A5: Variável | B5: Valor base | C5: -20% | D5: -10% | E5: +10% | F5: +20%
A6: Preço do gás (R$/botijão) | B6: ='Premissas'!B14 | C6: =('Premissas'!C33*(('Premissas'!B14*0.8)-'Premissas'!B15)+'Premissas'!C34*('Premissas'!B18-'Premissas'!B19))*(1-'Premissas'!B23)-'Premissas'!B65 | D6: =('Premissas'!C33*(('Premissas'!B14*0.9)-'Premissas'!B15)+'Premissas'!C34*('Premissas'!B18-'Premissas'!B19))*(1-'Premissas'!B23)-'Premissas'!B65 | E6: =('Premissas'!C33*(('Premissas'!B14*1.1)-'Premissas'!B15)+'Premissas'!C34*('Premissas'!B18-'Premissas'!B19))*(1-'Premissas'!B23)-'Premissas'!B65 | F6: =('Premissas'!C33*(('Premissas'!B14*1.2)-'Premissas'!B15)+'Premissas'!C34*('Premissas'!B18-'Premissas'!B19))*(1-'Premissas'!B23)-'Premissas'!B65
A7: Custo do gás (R$/botijão) | B7: ='Premissas'!B15 | C7: =('Premissas'!C33*('Premissas'!B14-('Premissas'!B15*0.8))+'Premissas'!C34*('Premissas'!B18-'Premissas'!B19))*(1-'Premissas'!B23)-'Premissas'!B65 | D7: =('Premissas'!C33*('Premissas'!B14-('Premissas'!B15*0.9))+'Premissas'!C34*('Premissas'!B18-'Premissas'!B19))*(1-'Premissas'!B23)-'Premissas'!B65 | E7: =('Premissas'!C33*('Premissas'!B14-('Premissas'!B15*1.1))+'Premissas'!C34*('Premissas'!B18-'Premissas'!B19))*(1-'Premissas'!B23)-'Premissas'!B65 | F7: =('Premissas'!C33*('Premissas'!B14-('Premissas'!B15*1.2))+'Premissas'!C34*('Premissas'!B18-'Premissas'!B19))*(1-'Premissas'!B23)-'Premissas'!B65
A8: Volume gás (botijões/mês) | B8: ='Premissas'!C33 | C8: =(('Premissas'!C33*0.8)*('Premissas'!B14-'Premissas'!B15)+'Premissas'!C34*('Premissas'!B18-'Premissas'!B19))*(1-'Premissas'!B23)-'Premissas'!B65 | D8: =(('Premissas'!C33*0.9)*('Premissas'!B14-'Premissas'!B15)+'Premissas'!C34*('Premissas'!B18-'Premissas'!B19))*(1-'Premissas'!B23)-'Premissas'!B65 | E8: =(('Premissas'!C33*1.1)*('Premissas'!B14-'Premissas'!B15)+'Premissas'!C34*('Premissas'!B18-'Premissas'!B19))*(1-'Premissas'!B23)-'Premissas'!B65 | F8: =(('Premissas'!C33*1.2)*('Premissas'!B14-'Premissas'!B15)+'Premissas'!C34*('Premissas'!B18-'Premissas'!B19))*(1-'Premissas'!B23)-'Premissas'!B65
A9: Preço da água (R$/galão) | B9: ='Premissas'!B18 | C9: =('Premissas'!C33*('Premissas'!B14-'Premissas'!B15)+'Premissas'!C34*(('Premissas'!B18*0.8)-'Premissas'!B19))*(1-'Premissas'!B23)-'Premissas'!B65 | D9: =('Premissas'!C33*('Premissas'!B14-'Premissas'!B15)+'Premissas'!C34*(('Premissas'!B18*0.9)-'Premissas'!B19))*(1-'Premissas'!B23)-'Premissas'!B65 | E9: =('Premissas'!C33*('Premissas'!B14-'Premissas'!B15)+'Premissas'!C34*(('Premissas'!B18*1.1)-'Premissas'!B19))*(1-'Premissas'!B23)-'Premissas'!B65 | F9: =('Premissas'!C33*('Premissas'!B14-'Premissas'!B15)+'Premissas'!C34*(('Premissas'!B18*1.2)-'Premissas'!B19))*(1-'Premissas'!B23)-'Premissas'!B65
A10: Custo da água (R$/galão) | B10: ='Premissas'!B19 | C10: =('Premissas'!C33*('Premissas'!B14-'Premissas'!B15)+'Premissas'!C34*('Premissas'!B18-('Premissas'!B19*0.8)))*(1-'Premissas'!B23)-'Premissas'!B65 | D10: =('Premissas'!C33*('Premissas'!B14-'Premissas'!B15)+'Premissas'!C34*('Premissas'!B18-('Premissas'!B19*0.9)))*(1-'Premissas'!B23)-'Premissas'!B65 | E10: =('Premissas'!C33*('Premissas'!B14-'Premissas'!B15)+'Premissas'!C34*('Premissas'!B18-('Premissas'!B19*1.1)))*(1-'Premissas'!B23)-'Premissas'!B65 | F10: =('Premissas'!C33*('Premissas'!B14-'Premissas'!B15)+'Premissas'!C34*('Premissas'!B18-('Premissas'!B19*1.2)))*(1-'Premissas'!B23)-'Premissas'!B65
A11: Volume água (galões/mês) | B11: ='Premissas'!C34 | C11: =('Premissas'!C33*('Premissas'!B14-'Premissas'!B15)+('Premissas'!C34*0.8)*('Premissas'!B18-'Premissas'!B19))*(1-'Premissas'!B23)-'Premissas'!B65 | D11: =('Premissas'!C33*('Premissas'!B14-'Premissas'!B15)+('Premissas'!C34*0.9)*('Premissas'!B18-'Premissas'!B19))*(1-'Premissas'!B23)-'Premissas'!B65 | E11: =('Premissas'!C33*('Premissas'!B14-'Premissas'!B15)+('Premissas'!C34*1.1)*('Premissas'!B18-'Premissas'!B19))*(1-'Premissas'!B23)-'Premissas'!B65 | F11: =('Premissas'!C33*('Premissas'!B14-'Premissas'!B15)+('Premissas'!C34*1.2)*('Premissas'!B18-'Premissas'!B19))*(1-'Premissas'!B23)-'Premissas'!B65
A12: Custos fixos (R$/mês) | B12: ='Premissas'!B65 | C12: =('Premissas'!C33*('Premissas'!B14-'Premissas'!B15)+'Premissas'!C34*('Premissas'!B18-'Premissas'!B19))*(1-'Premissas'!B23)-('Premissas'!B65*0.8) | D12: =('Premissas'!C33*('Premissas'!B14-'Premissas'!B15)+'Premissas'!C34*('Premissas'!B18-'Premissas'!B19))*(1-'Premissas'!B23)-('Premissas'!B65*0.9) | E12: =('Premissas'!C33*('Premissas'!B14-'Premissas'!B15)+'Premissas'!C34*('Premissas'!B18-'Premissas'!B19))*(1-'Premissas'!B23)-('Premissas'!B65*1.1) | F12: =('Premissas'!C33*('Premissas'!B14-'Premissas'!B15)+'Premissas'!C34*('Premissas'!B18-'Premissas'!B19))*(1-'Premissas'!B23)-('Premissas'!B65*1.2)
A14: LUCRO BASE (referência) | B14: =('Premissas'!C33*('Premissas'!B14-'Premissas'!B15)+'Premissas'!C34*('Premissas'!B18-'Premissas'!B19))*(1-'Premissas'!B23)-'Premissas'!B65 | C14: =('Premissas'!C33*('Premissas'!B14-'Premissas'!B15)+'Premissas'!C34*('Premissas'!B18-'Premissas'!B19))*(1-'Premissas'!B23)-'Premissas'!B65 | D14: =('Premissas'!C33*('Premissas'!B14-'Premissas'!B15)+'Premissas'!C34*('Premissas'!B18-'Premissas'!B19))*(1-'Premissas'!B23)-'Premissas'!B65 | E14: =('Premissas'!C33*('Premissas'!B14-'Premissas'!B15)+'Premissas'!C34*('Premissas'!B18-'Premissas'!B19))*(1-'Premissas'!B23)-'Premissas'!B65 | F14: =('Premissas'!C33*('Premissas'!B14-'Premissas'!B15)+'Premissas'!C34*('Premissas'!B18-'Premissas'!B19))*(1-'Premissas'!B23)-'Premissas'!B65
A16: LEGENDA:
A17: Cada célula mostra o lucro operacional mensal quando APENAS aquela variável muda.
A18: Compare com a linha "Lucro Base" para ver o impacto de cada variação.
A19: As variáveis mais sensíveis são as que mais mudam o lucro quando variam ±10-20%.

Sheet Kill Criteria
A1: KILL CRITERIA — QUANDO ENCERRAR O PROJETO
A3: Critério | B3: Limite | C3: Ação
A4: Zoneamento negado pela Prefeitura | B4: Parecer negativo | C4: ENCERRAR — não há alternativa no mesmo local
A5: Nenhuma distribuidora atende Anchieta | B5: Todas recusam | C5: ENCERRAR — sem fornecedor, sem negócio
A6: Vendas < breakeven por 3 meses consecutivos (após ramp-up) | B6: Mês 6 em diante | C6: AVALIAR: reduzir custos, intensificar marketing, ou ENCERRAR
A7: Prejuízo acumulado > R$ 15.000 (excluindo investimento) | B7: A qualquer momento | C7: ENCERRAR — vender estoque e recuperar capital
A8: Concorrente abre revenda no mesmo quarteirão | B8: A qualquer momento | C8: AVALIAR: diferenciar por entrega rápida ou ENCERRAR se inviável
A9: Regulamentação nova da ANP inviabiliza operação | B9: A qualquer momento | C9: ENCERRAR — adaptar se possível, encerrar se não
A10: Custo de adequação > R$ 30.000 | B10: Antes de iniciar obra | C10: REAVALIAR — a conta pode não fechar
